Workbook
Name GM: #REF!
Name MG: #REF!
Name SMG: #REF!
Name コーポレート: 方針!$E$30:$E$30
Name スタッフ: #REF!
Name バックオフィス戦略本部: 方針!$E$14:$E$18
Name 営業統括本部: 方針!$E$6:$E$10

Sheet 方針
C2: ■方針一覧
D4: コーポレート
D5: No. | E5: 項目 | F5: 詳細
D6: 1 | E6: CX コーポレートトランスフォーメーション | F6: ・理念体系の再定義と実現 ・組織再編、ガバナンスとコンプライアンスの強化 ・情報発信（Gopalポータル）の強化
D7: =D6+1 | E7: BX ビジネストランスフォーメーション | F7: ・管理会計を用いたビジネスの見える化 ・ビジネスモデルの変革（ダイレクト比率向上含む） ・業務フローの見直し
D8: =D7+1 | E8: DX デジタルトランスフォーメーション | F8: ・ペーパーレス、メール/電話文化の見直し ・M365製品（Teams、Sharepoint等）による業務効率化 ・クラウドサインにより契約電子化 ・UPSIDER、freeeによる経理業務電子化
D9: =D8+1 | E9: EX エンプロイートランスフォーメーション | F9: ・コミュニケーション向上（1on1、インクルージョン） ・人事制度の刷新 ・若手/女性の役職者（拠点長以上）登用 ・マネージャー研修の拡充 ・従業員アンケートの実施
D10: =D9+1 | E10: UX ユーザーエクスペリエンス | F10: ・充実した研修制度 ・デジタル化によるわかりやすいサービスの提供 ・DA様アンケートの実施
D12: 営業本部東・西日本輸送部
D13: No. | E13: 項目 | F13: 詳細
D14: 1 | E14: 売上・拠点拡大 | F14: 担当拠点の稼働台数維持・拡大、およびセール期の増車需要への対応体制の整備。 月次売上予測の精度向上による計画的な拠点運営の実現。 ⇒指標：増車率
D15: =D14+1 | E15: 配送品質・スコアカードの向上 | F15: 日次データに基づく品質状況の把握と課題への迅速な対処。 スコアカード各指標の継続的な改善・維持の徹底。 ⇒指標：各種スコアカードのスコア
D16: =D15+1 | E16: 稼働コンプライアンスの徹底 | F16: ドライバーの稼働・休息時間の日次管理と違反発生前の是正。 法令・社内ルール遵守の現場全体への浸透。 ⇒指標：コンプライアンス違反、60時間超え、1日稼働時間、休息時間
D17: =D16+1 | E17: 組織・業務効率化 | F17: 業務標準化による担当者によらない安定した業務品質の確保。 業務プロセス見直しによる生産性向上とコスト削減の両立。 ⇒指標：SOP（作業手順書）
D18: =D17+1 | E18: 働き方改革 | F18: 時間外労働の適正化と計画的な有給取得の推進。 心身の健康維持を前提とした持続可能な就労環境の整備。 ⇒指標：残業時間、有給取得率
D20: 営業本部営業企画室
D21: No. | E21: 項目 | F21: 詳細
D22: 1 | E22: 中長期計画の策定・推進 | F22: 業界トレンド・競合動向・外部パートナーとの関係構築を踏まえた会社の方向性の立案。 3カ年計画の策定と進捗管理。 ⇒指標：計画策定・更新状況、Amazon売上比率
D23: =D22+1 | E23: 予算・KPI管理 | F23: 各部門・拠点の予算策定と進捗管理。 市場分析・新規事業の収支シミュレーションを通じた収益構造の改善。 ⇒指標：予算達成率、新規事業提案件数
D24: =D23+1 | E24: コンプライアンス・リスク管理の徹底 | F24: 法令・社内ルールの遵守徹底とリスクの予防的管理。 自担当領域のリスクを把握し、会社全体のガバナンス強化に貢献する。 ⇒指標：研修受講率、法令対応件数
D25: =D24+1 | E25: 組織・業務効率化 | F25: 業務標準化による担当者によらない安定した業務品質の確保。 業務プロセス見直しによる生産性向上とコスト削減の両立。 ⇒指標：SOP整備率、ペーパーレス化率
D26: =D25+1 | E26: 働き方改革 | F26: 時間外労働の適正化と計画的な有給取得の推進。 心身の健康維持を前提とした持続可能な就労環境の整備。 ⇒指標：残業時間、有給取得率
D28: 管理本部管理部
D29: No. | E29: 項目 | F29: 詳細
D30: 1 | E30: 情報整備・データ活用の推進 | F30: 会社の現状を数字で把握・提供できる体制の構築。 各部門の意思決定を支える情報基盤の整備。 ⇒指標：レポート定期提供、データ精度
D31: =D30+1 | E31: 各部門との連携強化 | F31: 各部門のニーズを的確に把握し、迅速かつ的確に対応できる体制づくり。 管理部が現場を理解し、先回りして動ける存在へ。 ⇒指標：対応リードタイム、問い合わせ解決率
D32: =D31+1 | E32: コンプライアンス・リスク管理の徹底 | F32: 法令・社内ルールの遵守徹底とリスクの予防的管理。 自担当領域のリスクを把握し、会社全体のガバナンス強化に貢献する。 ⇒指標：研修受講率、法令対応件数
D33: =D32+1 | E33: 組織・業務効率化 | F33: 業務標準化による担当者によらない安定した業務品質の確保。 業務プロセス見直しによる生産性向上とコスト削減の両立。 ⇒指標：SOP整備率、ペーパーレス化率
D34: =D33+1 | E34: 働き方改革 | F34: 時間外労働の適正化と計画的な有給取得の推進。 心身の健康維持を前提とした持続可能な就労環境の整備。 ⇒指標：残業時間、有給取得率

Sheet 営業
D2: パフォーマンスシート | G2: 面談実施日：
G3: マネージャー：
D4: 対象期間： | E4: 2026年10月1日～2027年3月31日
D6: 所属部署： | G6: 個人総合評価：
D7: 氏名： | G7: マネージャー総合評価：
D9: 設定項目1
D10: =方針!E14
D12: 自己評価
D15: 個人目標
D21: 個人目標を達成するための具体的な行動（KPI）
D29: 振り返り
D37: マネージャー評価
D40: マネージャーからのコメント
D48: 設定項目2
D49: =方針!E15
D51: 個人目標
D57: 個人目標を達成するための具体的な行動（KPI）
D65: 自己評価
D68: 振り返り
D76: マネージャー評価
D79: マネージャーからのコメント
D87: 設定項目3
D88: =方針!E16
D90: 個人目標
D96: 個人目標を達成するための具体的な行動（KPI）
D104: 自己評価
D107: 振り返り
D115: マネージャー評価
D118: マネージャーからのコメント
D126: 設定項目4
D127: =方針!E17
D129: 個人目標
D135: 個人目標を達成するための具体的な行動（KPI）
D143: 自己評価
D146: 振り返り
D154: マネージャー評価
D157: マネージャーからのコメント
D165: 設定項目5
D166: =方針!E18
D168: 個人目標
...

Sheet 営業企画
D2: パフォーマンスシート | G2: 面談実施日：
G3: マネージャー：
D4: 対象期間： | E4: 2026年10月1日～2027年3月31日
D6: 所属部署： | G6: 個人総合評価：
D7: 氏名： | G7: マネージャー総合評価：
D9: 設定項目1
D10: =方針!E22
D12: 自己評価
D15: 個人目標
D21: 個人目標を達成するための具体的な行動（KPI）
D29: 振り返り
D37: マネージャー評価
D40: マネージャーからのコメント
D48: 設定項目2
D49: =方針!E23
D51: 個人目標
D57: 個人目標を達成するための具体的な行動（KPI）
D65: 自己評価
D68: 振り返り
D76: マネージャー評価
D79: マネージャーからのコメント
D87: 設定項目3
D88: =方針!E24
D90: 個人目標
D96: 個人目標を達成するための具体的な行動（KPI）
D104: 自己評価
D107: 振り返り
D115: マネージャー評価
D118: マネージャーからのコメント
D126: 設定項目4
D127: =方針!E25
D129: 個人目標
D135: 個人目標を達成するための具体的な行動（KPI）
D143: 自己評価
D146: 振り返り
D154: マネージャー評価
D157: マネージャーからのコメント
D165: 設定項目5
D166: =方針!E26
D168: 個人目標
...

Sheet 管理部
D2: パフォーマンスシート | G2: 面談実施日：
G3: マネージャー：
D4: 対象期間： | E4: 2026年10月1日～2027年3月31日
D6: 所属部署： | E6: 管理本部 管理部 | G6: 個人総合評価：
D7: 氏名： | E7: 加賀谷 雄登 | G7: マネージャー総合評価：
D9: 設定項目1
D10: =方針!E30
D12: 自己評価
D15: 個人目標
D16: 登録業務・監査業務・リース契約業務の件数と不備状況を数字で把握し、業務改善につながる情報として提供できるようになる。
D21: 個人目標を達成するための具体的な行動（KPI）
D22: ・業務件数と不備件数を月次で集計し、毎月5営業日以内に作成する。（6回/6回） ・不備の原因を分類し、多い原因について対策案を四半期に1回提案する。 ・集計の定義や入力ルールを記録し、データの精度を保つ。
D29: 振り返り
D37: マネージャー評価
D40: マネージャーからのコメント
D48: 設定項目2
D49: =方針!E31
D51: 個人目標
D52: 拠点・協力会社との連携を仕組み化し、書類不備の再発を防ぐ。
D57: 個人目標を達成するための具体的な行動（KPI）
D58: ・拠点とのMTGを月2回、定例の日程を固定して実施する。 ・各拠点や協力会社からの問い合わせは当日中に対応する。（対応率100%） ・書類不備の内容と件数を記録し、同じ不備の再発を前期より減らす。
D65: 自己評価
D68: 振り返り
D76: マネージャー評価
D79: マネージャーからのコメント
D87: 設定項目3
D88: =方針!E32
D90: 個人目標
D91: 契約書のコンプライアンスを正しく理解し、チェック精度を高めて知識をチームに共有する。
D96: 個人目標を達成するための具体的な行動（KPI）
D97: ・登録業務のダブルチェックを継続し、チェック漏れによる差戻しをゼロにする。 ・ミスや不明点は当日中に報告・相談する。 ・フリーランス法・下請法の講義または学習を1回以上行い、学んだ内容をチーム内で共有する。（1回）
D104: 自己評価
D107: 振り返り
D115: マネージャー評価
D118: マネージャーからのコメント
D126: 設定項目4
D127: =方針!E33
D129: 個人目標
D130: 登録・リース契約業務を標準化し、担当者によらず同じ品質で対応できる状態にする。
D135: 個人目標を達成するための具体的な行動（KPI）
...
